<?xml version="1.0"?>
<robot name="gurdy">
    <material name="red">
        <color rgba="0.8 0.0 0.0 0.8" />
    </material>
    <material name="black">
        <color rgba="1 1 1 0.8" />
    </material>
    <material name="gray">
        <color rgba="0.3 0.3 0.3 1" />
    </material>
    <material name="blue">
        <color rgba="0.0 0.0 1.0 1" />
    </material>
    <material name="green">
        <color rgba="0.0 1.0 0.0 1" />
    </material>
    <material name="pink">
        <color rgba="0.254 0.127 0.156 1" />
    </material>
    <link name="base_link">
        <inertial>
            <origin xyz="0 0 0" rpy="0 0 0" />
            <mass value="0.001" />
            <inertia ixx="0" ixy="0.0" ixz="0.0" iyy="0" iyz="0.0" izz="0" />
        </inertial>
        <collision>
            <origin rpy="0.0 0 0" xyz="0 0 0.0" />
            <geometry>
                <box size="0.01 0.01 0.01" />
            </geometry>
        </collision>
        <visual>
            <material name="black"/>
            <origin xyz="0 0 0" rpy="0 0 0"/>
            <geometry>
                <box size="0.01 0.01 0.01"/>
            </geometry>
        </visual>
    </link>
    <link name="head_link">
        <inertial>
            <origin xyz="0 0 0.02" rpy="0 0 0" />
            <mass value="0.01" />
            <inertia ixx="7.58333333333e-06" ixy="0.0" ixz="0.0" iyy="7.58333333333e-06" iyz="0.0" izz="1.25e-05" />
        </inertial>
        <collision>
            <origin rpy="0.0 0 0" xyz="0 0 0.02" />
            <geometry>
                <cylinder radius="0.05" length="0.04" />
            </geometry>
        </collision>
        <visual>
            <material name="red"/>
            <origin xyz="0 0 0" rpy="0 0 0"/>
            <geometry>
                <mesh filename="package://my_mira_description/models/gurdy/meshes/gurdy_head_v2.dae" />
            </geometry>
        </visual>
    </link>
    <joint name="base_head_joint" type="fixed">
        <parent link="base_link" />
        <child link="head_link" />
        <origin xyz="0.0 0.0 0.005" rpy="0 0 0" />
    </joint>
    <link name="upper_leg_M1_link">
        <inertial>
            <origin xyz="0 0 -0.03" rpy="0 0 0" />
            <mass value="0.01" />
            <inertia ixx="2.10583333333e-06" ixy="0.0" ixz="0.0" iyy="2.10583333333e-06" iyz="0.0" izz="4.5e-08" />
        </inertial>
        <collision>
            <origin rpy="0.0 0 0" xyz="0 0 -0.03" />
            <geometry>
                <cylinder radius="0.003" length="0.05" />
            </geometry>
        </collision>
        <visual>
            <material name="gray"/>
            <origin xyz="0 0.0 -0.06" rpy="0 0 0"/>
            <geometry>
                <mesh filename="package://my_mira_description/models/gurdy/meshes/gurdy_higherleg_v2.dae" />
            </geometry>
        </visual>
    </link>
    <joint name="head_upper_leg_M1" type="revolute">
        <parent link="head_link" />
        <child link="upper_leg_M1_link" />
        <origin xyz="0.02365 -0.0090359 -0.008" rpy="0 0 -0.5235" />
        <limit effort="30" velocity="1.0" lower="-1.5707" upper="1.5707" />
        <axis xyz="0 1 0" />
    </joint>
    <link name="lower_leg_M1_link">
        <visual>
            <material name="red"/>
            <origin xyz="0 0.0 -0.06" rpy="0 0 0"/>
            <geometry>
                <mesh filename="package://my_mira_description/models/gurdy/meshes/gurdy_lowerleg_v2.dae" />
            </geometry>
        </visual>
    </link>
    <joint name="upper_leg_M1_lower_leg_M1" type="revolute">
        <parent link="upper_leg_M1_link" />
        <child link="lower_leg_M1_link" />
        <origin xyz="0.0 -0.006 -0.06" rpy="0 0 0" />
        <limit effort="30" velocity="1.0" lower="-1.5707" upper="1.5707" />
        <axis xyz="0 1 0" />
    </joint>
    <link name="foot_M1">
        <visual>
            <material name="blue"/>
            <origin xyz="0 0 0" rpy="0 0 0"/>
            <geometry>
                <sphere radius="0.008"/>
            </geometry>
        </visual>
    </link>
    <joint name="lower_leg_M1_foot_M1" type="fixed">
        <parent link="lower_leg_M1_link" />
        <child link="foot_M1" />
        <origin xyz="0.0 0.0 -0.060" rpy="0 0 0" />
    </joint>
    <link name="upper_leg_M2_link">
        <inertial>
            <origin xyz="0 0 -0.03" rpy="0 0 0" />
            <mass value="0.01" />
            <inertia ixx="2.10583333333e-06" ixy="0.0" ixz="0.0" iyy="2.10583333333e-06" iyz="0.0" izz="4.5e-08" />
        </inertial>
        <collision>
            <origin rpy="0.0 0 0" xyz="0 0 -0.03" />
            <geometry>
                <cylinder radius="0.003" length="0.05" />
            </geometry>
        </collision>
        <visual>
            <material name="gray"/>
            <origin xyz="0 -0.0 -0.06" rpy="0 0 0"/>
            <geometry>
                <mesh filename="package://my_mira_description/models/gurdy/meshes/gurdy_higherleg_v2.dae" />
            </geometry>
        </visual>
    </link>
    <joint name="head_upper_leg_M2" type="revolute">
        <parent link="head_link" />
        <child link="upper_leg_M2_link" />
        <origin xyz="-0.0195 -0.01569 -0.008" rpy="0 0 0.5235" />
        <limit effort="30" velocity="1.0" lower="-1.5707" upper="1.5707" />
        <axis xyz="0 1 0" />
    </joint>
    <link name="lower_leg_M2_link">
        <visual>
            <material name="red"/>
            <origin xyz="0 0 -0.06" rpy="0 0 0"/>
            <geometry>
                <mesh filename="package://my_mira_description/models/gurdy/meshes/gurdy_lowerleg_v2.dae" />
            </geometry>
        </visual>
    </link>
    <joint name="upper_leg_M2_lower_leg_M2" type="revolute">
        <parent link="upper_leg_M2_link" />
        <child link="lower_leg_M2_link" />
        <origin xyz="0.0 -0.006 -0.06" rpy="0 0 0" />
        <limit effort="30" velocity="1.0" lower="-1.5707" upper="1.5707" />
        <axis xyz="0 1 0" />
    </joint>
    <link name="foot_M2">
        <visual>
            <material name="green"/>
            <origin xyz="0 0.0 0.0" rpy="0 0 0"/>
            <geometry>
                <sphere radius="0.008"/>
            </geometry>
        </visual>
    </link>
    <joint name="lower_leg_M2_foot_M2" type="fixed">
        <parent link="lower_leg_M2_link" />
        <child link="foot_M2" />
        <origin xyz="0.0 0.0 -0.06" rpy="0 0 0" />
    </joint>
    <link name="upper_leg_M3_link">
        <inertial>
            <origin xyz="0 0 -0.03" rpy="0 0 0" />
            <mass value="0.01" />
            <inertia ixx="2.10583333333e-06" ixy="0.0" ixz="0.0" iyy="2.10583333333e-06" iyz="0.0" izz="4.5e-08" />
        </inertial>
        <collision>
            <origin rpy="0.0 0 0" xyz="0 0 -0.03" />
            <geometry>
                <cylinder radius="0.003" length="0.05" />
            </geometry>
        </collision>
        <visual>
            <material name="gray"/>
            <origin xyz="0.0 0.0 -0.06" rpy="0 0 0"/>
            <geometry>
                <mesh filename="package://my_mira_description/models/gurdy/meshes/gurdy_higherleg_v2.dae" />
            </geometry>
        </visual>
    </link>
    <joint name="head_upper_leg_M3" type="revolute">
        <parent link="head_link" />
        <child link="upper_leg_M3_link" />
        <origin xyz="-0.004 0.025 -0.008" rpy="0 0 1.57079" />
        <limit effort="30" velocity="1.0" lower="-1.5707" upper="1.5707" />
        <axis xyz="0 1 0" />
    </joint>
    <link name="lower_leg_M3_link">
        <visual>
            <material name="red"/>
            <origin xyz="0 0.0 -0.06" rpy="0 0 0"/>
            <geometry>
                <mesh filename="package://my_mira_description/models/gurdy/meshes/gurdy_lowerleg_v2.dae" />
            </geometry>
        </visual>
    </link>
    <joint name="upper_leg_M3_lower_leg_M3" type="revolute">
        <parent link="upper_leg_M3_link" />
        <child link="lower_leg_M3_link" />
        <origin xyz="0.0 -0.006 -0.06" rpy="0 0 0" />
        <limit effort="30" velocity="1.0" lower="-1.5707" upper="1.5707" />
        <axis xyz="0 1 0" />
    </joint>
    <link name="foot_M3">
        <visual>
            <material name="pink"/>
            <origin xyz="0 0 0" rpy="0 0 0"/>
            <geometry>
                <sphere radius="0.008"/>
            </geometry>
        </visual>
    </link>
    <joint name="lower_leg_M3_foot_M3" type="fixed">
        <parent link="lower_leg_M3_link" />
        <child link="foot_M3" />
        <origin xyz="0.0 0.0 -0.06" rpy="0 0 0" />
    </joint>
    <gazebo reference="head_link">
        <kp>10000.0</kp>
        <kd>10000.0</kd>
        <mu1>10.0</mu1>
        <mu2>10.0</mu2>
        <material>Gazebo/Red</material>
    </gazebo>
    <gazebo reference="base_link">
        <kp>10000.0</kp>
        <kd>10000.0</kd>
        <mu1>10.0</mu1>
        <mu2>10.0</mu2>
        <material>Gazebo/Black</material>
    </gazebo>
    <gazebo reference="upper_leg_M1_link">
        <kp>10000.0</kp>
        <kd>10000.0</kd>
        <mu1>10.0</mu1>
        <mu2>10.0</mu2>
        <material>Gazebo/Black</material>
    </gazebo>
    <gazebo reference="upper_leg_M2_link">
        <kp>10000.0</kp>
        <kd>10000.0</kd>
        <mu1>10.0</mu1>
        <mu2>10.0</mu2>
        <material>Gazebo/Black</material>
    </gazebo>
    <gazebo reference="upper_leg_M3_link">
        <kp>10000.0</kp>
        <kd>10000.0</kd>
        <mu1>10.0</mu1>
        <mu2>10.0</mu2>
        <material>Gazebo/Black</material>
    </gazebo>
</robot>