<?xml version="1.0"?>
<robot name="gurdy">
    <material name="red">
        <color rgba="0.8 0.0 0.0 0.8" />
    </material>
    <material name="black">
        <color rgba="1 1 1 0.8" />
    </material>
    <material name="gray">
        <color rgba="0.3 0.3 0.3 1" />
    </material>
    <material name="blue">
        <color rgba="0.0 0.0 1.0 1" />
    </material>
    <material name="green">
        <color rgba="0.0 1.0 0.0 1" />
    </material>
    <material name="pink">
        <color rgba="0.254 0.127 0.156 1" />
    </material>
    <link name="base_link">
        <visual>
            <material name="black"/>
            <origin xyz="0 0 0" rpy="0 0 0"/>
            <geometry>
                <box size="0.01 0.01 0.01"/>
            </geometry>
        </visual>
    </link>
    <link name="head_link">
        <visual>
            <material name="red"/>
            <origin xyz="0 0 0" rpy="0 0 0"/>
            <geometry>
                <mesh filename="package://my_mira_description/models/gurdy/meshes/gurdy_head_v2.dae" />
            </geometry>
        </visual>
    </link>
    <joint name="base_head_joint" type="fixed">
        <parent link="base_link" />
        <child link="head_link" />
        <origin xyz="0.0 0.0 0.005" rpy="0 0 0" />
    </joint>
    <link name="upper_leg_M1_link">
        <visual>
            <material name="gray"/>
            <origin xyz="0 0.0 -0.06" rpy="0 0 0"/>
            <geometry>
                <mesh filename="package://my_mira_description/models/gurdy/meshes/gurdy_higherleg_v2.dae" />
            </geometry>
        </visual>
    </link>
    <joint name="head_upper_leg_M1" type="revolute">
        <parent link="head_link" />
        <child link="upper_leg_M1_link" />
        <origin xyz="0.02365 -0.0090359 -0.008" rpy="0 0 -0.5235" />
        <limit effort="30" velocity="1.0" lower="-1.5707" upper="1.5707" />
        <axis xyz="0 1 0" />
    </joint>
    <link name="lower_leg_M1_link">
        <visual>
            <material name="red"/>
            <origin xyz="0 0.0 -0.06" rpy="0 0 0"/>
            <geometry>
                <mesh filename="package://my_mira_description/models/gurdy/meshes/gurdy_lowerleg_v2.dae" />
            </geometry>
        </visual>
    </link>
    <joint name="upper_leg_M1_lower_leg_M1" type="revolute">
        <parent link="upper_leg_M1_link" />
        <child link="lower_leg_M1_link" />
        <origin xyz="0.0 -0.006 -0.06" rpy="0 0 0" />
        <limit effort="30" velocity="1.0" lower="-1.5707" upper="1.5707" />
        <axis xyz="0 1 0" />
    </joint>
    <link name="foot_M1">
        <visual>
            <material name="blue"/>
            <origin xyz="0 0 0" rpy="0 0 0"/>
            <geometry>
                <sphere radius="0.008"/>
            </geometry>
        </visual>
    </link>
    <joint name="lower_leg_M1_foot_M1" type="fixed">
        <parent link="lower_leg_M1_link" />
        <child link="foot_M1" />
        <origin xyz="0.0 0.0 -0.060" rpy="0 0 0" />
    </joint>
    <link name="upper_leg_M2_link">
        <visual>
            <material name="gray"/>
            <origin xyz="0 -0.0 -0.06" rpy="0 0 0"/>
            <geometry>
                <mesh filename="package://my_mira_description/models/gurdy/meshes/gurdy_higherleg_v2.dae" />
            </geometry>
        </visual>
    </link>
    <joint name="head_upper_leg_M2" type="revolute">
        <parent link="head_link" />
        <child link="upper_leg_M2_link" />
        <origin xyz="-0.0195 -0.01569 -0.008" rpy="0 0 0.5235" />
        <limit effort="30" velocity="1.0" lower="-1.5707" upper="1.5707" />
        <axis xyz="0 1 0" />
    </joint>
    <link name="lower_leg_M2_link">
        <visual>
            <material name="red"/>
            <origin xyz="0 0 -0.06" rpy="0 0 0"/>
            <geometry>
                <mesh filename="package://my_mira_description/models/gurdy/meshes/gurdy_lowerleg_v2.dae" />
            </geometry>
        </visual>
    </link>
    <joint name="upper_leg_M2_lower_leg_M2" type="revolute">
        <parent link="upper_leg_M2_link" />
        <child link="lower_leg_M2_link" />
        <origin xyz="0.0 -0.006 -0.06" rpy="0 0 0" />
        <limit effort="30" velocity="1.0" lower="-1.5707" upper="1.5707" />
        <axis xyz="0 1 0" />
    </joint>
    <link name="foot_M2">
        <visual>
            <material name="green"/>
            <origin xyz="0 0.0 0.0" rpy="0 0 0"/>
            <geometry>
                <sphere radius="0.008"/>
            </geometry>
        </visual>
    </link>
    <joint name="lower_leg_M2_foot_M2" type="fixed">
        <parent link="lower_leg_M2_link" />
        <child link="foot_M2" />
        <origin xyz="0.0 0.0 -0.06" rpy="0 0 0" />
    </joint>
    <link name="upper_leg_M3_link">
        <visual>
            <material name="gray"/>
            <origin xyz="0.0 0.0 -0.06" rpy="0 0 0"/>
            <geometry>
                <mesh filename="package://my_mira_description/models/gurdy/meshes/gurdy_higherleg_v2.dae" />
            </geometry>
        </visual>
    </link>
    <joint name="head_upper_leg_M3" type="revolute">
        <parent link="head_link" />
        <child link="upper_leg_M3_link" />
        <origin xyz="-0.004 0.025 -0.008" rpy="0 0 1.57079" />
        <limit effort="30" velocity="1.0" lower="-1.5707" upper="1.5707" />
        <axis xyz="0 1 0" />
    </joint>
    <link name="lower_leg_M3_link">
        <visual>
            <material name="red"/>
            <origin xyz="0 0.0 -0.06" rpy="0 0 0"/>
            <geometry>
                <mesh filename="package://my_mira_description/models/gurdy/meshes/gurdy_lowerleg_v2.dae" />
            </geometry>
        </visual>
    </link>
    <joint name="upper_leg_M3_lower_leg_M3" type="revolute">
        <parent link="upper_leg_M3_link" />
        <child link="lower_leg_M3_link" />
        <origin xyz="0.0 -0.006 -0.06" rpy="0 0 0" />
        <limit effort="30" velocity="1.0" lower="-1.5707" upper="1.5707" />
        <axis xyz="0 1 0" />
    </joint>
    <link name="foot_M3">
        <visual>
            <material name="pink"/>
            <origin xyz="0 0 0" rpy="0 0 0"/>
            <geometry>
                <sphere radius="0.008"/>
            </geometry>
        </visual>
    </link>
    <joint name="lower_leg_M3_foot_M3" type="fixed">
        <parent link="lower_leg_M3_link" />
        <child link="foot_M3" />
        <origin xyz="0.0 0.0 -0.06" rpy="0 0 0" />
    </joint>
</robot>