<?xml version="1.0"?>
<robot name="mira">
	<material name="red">
		<color rgba="0.8 0.0 0.0 0.8" />
	</material>
	<material name="green">
		<color rgba="0 0.8 0 0.8" />
	</material>
	<material name="blue">
		<color rgba="0 0.0 0.8 0.8" />
	</material>
	<material name="grey">
		<color rgba="0.3 0.3 0.3 0.8" />
	</material>
	<material name="black">
		<color rgba="0.0 0.0 0.0 1" />
	</material>
	<link name="base_link">
		<visual>
			<material name="green" />
			<origin rpy="0 0 0" xyz="0 0 0" />
			<geometry>
				<cylinder radius="0.06" length="0.09" />
			</geometry>
		</visual>
	</link>
	<link name="roll_M1_link">
		<visual>
			<material name="red" />
			<origin rpy="0 0 0" xyz="0 0 0" />
			<geometry>
				<cylinder length="0.005" radius="0.01" />
			</geometry>
		</visual>
	</link>
	<link name="pitch_M2_link">
		<visual>
			<material name="green" />
			<origin rpy="1.571 0 0" xyz="0 0 0" />
			<geometry>
				<cylinder length="0.005" radius="0.01" />
			</geometry>
		</visual>
	</link>
	<link name="yaw_M3_link">
		<visual>
			<material name="blue" />
			<origin rpy="0 0 0" xyz="0 0 0" />
			<geometry>
				<cylinder length="0.005" radius="0.01" />
			</geometry>
		</visual>
	</link>
	<link name="head_link">
		<visual>
			<material name="grey" />
			<origin rpy="0 0 0" xyz="0 0 0" />
			<geometry>
				<sphere radius="0.06" />
			</geometry>
		</visual>
	</link>
	<link name="left_eye_link">
		<visual>
			<material name="black" />
			<origin rpy="0 1.571 0" xyz="0 0 0" />
			<geometry>
				<cylinder length="0.00525" radius="0.00525" />
			</geometry>
		</visual>
	</link>
	<link name="right_eye_link">
		<visual>
			<material name="black" />
			<origin rpy="0 1.571 0" xyz="0 0 0" />
			<geometry>
				<cylinder length="0.00525" radius="0.00525" />
			</geometry>
		</visual>
	</link>
	<link name="camera_link">
		<visual>
			<material name="black" />
			<origin rpy="0 1.571 0" xyz="0 0 0" />
			<geometry>
				<box size="0.0005 0.0005 0.0005" />
			</geometry>
		</visual>
	</link>
	<joint name="roll_joint" type="revolute">
		<parent link="base_link" />
		<child link="roll_M1_link" />
		<origin xyz="0.0 0.0 0.045" rpy="0 0 0" />
		<limit lower="-0.2" upper="0.2" effort="0.1" velocity="0.005" />
		<axis xyz="1 0 0" />
	</joint>
	<joint name="pitch_joint" type="revolute">
		<parent link="roll_M1_link" />
		<child link="pitch_M2_link" />
		<origin xyz="0.0 0.0 0.0025" rpy="0 0 0" />
		<limit lower="-0.2" upper="0.2" effort="0.1" velocity="0.005" />
		<axis xyz="0 1 0" />
	</joint>
	<joint name="yaw_joint" type="revolute">
		<parent link="pitch_M2_link" />
		<child link="yaw_M3_link" />
		<origin xyz="0.0 0.0 0.0" rpy="0 0 0" />
		<limit lower="-0.2" upper="0.2" effort="0.1" velocity="0.005" />
		<axis xyz="0 0 1" />
	</joint>
	<joint name="base_head_joint" type="fixed">
		<parent link="yaw_M3_link" />
		<child link="head_link" />
		<origin xyz="0.0 0.0 0.0" rpy="0 0 0" />
		<limit lower="-0.2" upper="0.2" effort="0.1" velocity="0.005" />
		<axis xyz="1 0 0" />
	</joint>
	<joint name="head_lefteye_joint" type="fixed">
		<parent link="head_link" />
		<child link="left_eye_link" />
		<origin xyz="0.0470931 0.0271892 0.0253571" rpy="0 0 0">
			<axis xyz="1 0 0" />
		</origin>
	</joint>
	<joint name="head_righteye_joint" type="fixed">
		<parent link="head_link" />
		<child link="right_eye_link" />
		<origin xyz="0.0470931 -0.0271892 0.0253571" rpy="0 0 0">
			<axis xyz="1 0 0" />
		</origin>
	</joint>
	<joint name="head_camera_joint" type="fixed">
		<parent link="head_link" />
		<child link="camera_link" />
		<origin xyz="0.0424264 0 0.0424264" rpy="0 0 0">
			<axis xyz="1 0 0" />
		</origin>
	</joint>
</robot>
